Workbook
Name Admin_Cost_per_day: #REF!
Name Admin.costperday: 'ModelwithRP$150LCF$50'!$H$19
Name Admin.costperday: 'ModelwithRP$150LCF$70'!$H$19
Name Admin.costperday: 'ModelwithRP$180LCF$50'!$H$19
Name Admin.costperday: 'ModelwithRP$180LCF$70'!$H$19
Name Admin.costperday: '1.c Model Simulated data'!$H$19
Name Admin.costperroom: 'ModelwithRP$150LCF$50'!$H$19
Name Admin.costperroom: 'ModelwithRP$150LCF$70'!$H$19
Name Admin.costperroom: 'ModelwithRP$180LCF$50'!$H$19
Name Admin.costperroom: 'ModelwithRP$180LCF$70'!$H$19
Name Admin.costperroom: '1.c Model Simulated data'!$H$19
Name Buffet_Breakfast_cost_per_room: #REF!
Name buffet.breakfas.costperroom: 'ModelwithRP$150LCF$50'!$H$17
Name buffet.breakfas.costperroom: 'ModelwithRP$150LCF$70'!$H$17
Name buffet.breakfas.costperroom: 'ModelwithRP$180LCF$50'!$H$17
Name buffet.breakfas.costperroom: 'ModelwithRP$180LCF$70'!$H$17
Name buffet.breakfas.costperroom: '1.c Model Simulated data'!$H$17
Name cancellation.fee: 'ModelwithRP$150LCF$50'!$H$13
Name cancellation.fee: 'ModelwithRP$150LCF$70'!$H$13
Name cancellation.fee: 'ModelwithRP$180LCF$50'!$H$13
Name cancellation.fee: 'ModelwithRP$180LCF$70'!$H$13
Name cancellation.fee: '1.c Model Simulated data'!$H$13
Name Contribution_margin_per_unit: [1]Model!$C$4
Name Cost_of_parts_per_unit: [1]Model!$H$5
Name Daily_Miscellaneous_expense: #REF!
Name daily_miscellaneous_expense1: #REF!
Name daily_miscellaneous_expenses: #REF!
Name Daily_Online_Reservation: #REF!
Name daily_online_reservation1: #REF!
Name daily_online_reservations: #REF!
Name daily.miscellaneous.expense: 'ModelwithRP$150LCF$50'!#REF!
Name daily.miscellaneous.expense: 'ModelwithRP$150LCF$70'!#REF!
Name daily.miscellaneous.expense: 'ModelwithRP$180LCF$50'!#REF!
Name daily.miscellaneous.expense: 'ModelwithRP$180LCF$70'!#REF!
Name daily.miscellaneous.expense: '1.c Model Simulated data'!#REF!
Name daily.online.reservation: 'ModelwithRP$150LCF$50'!$H$4
Name daily.online.reservation: 'ModelwithRP$150LCF$70'!$H$4
Name daily.online.reservation: 'ModelwithRP$180LCF$50'!$H$4
Name daily.online.reservation: 'ModelwithRP$180LCF$70'!$H$4
Name daily.online.reservation: '1.c Model Simulated data'!$H$4
Name dailyrevenue: 'ModelwithRP$150LCF$50'!$C$8
Name dailyrevenue: 'ModelwithRP$150LCF$70'!$C$8
Name dailyrevenue: 'ModelwithRP$180LCF$50'!$C$8
Name dailyrevenue: 'ModelwithRP$180LCF$70'!$C$8
Name dailyrevenue: '1.c Model Simulated data'!$C$8
Name Demand: [1]Model!$H$6
Name Direct_labour_cost_per_unit: [1]Model!$H$4
Name First_year_profit: [1]Model!$C$6
Name House_Keeping_Cost_per_room: #REF!
Name Housekeeping.costperroom: 'ModelwithRP$150LCF$50'!#REF!
Name Housekeeping.costperroom: 'ModelwithRP$150LCF$70'!#REF!
Name Housekeeping.costperroom: 'ModelwithRP$180LCF$50'!#REF!
Name Housekeeping.costperroom: 'ModelwithRP$180LCF$70'!#REF!
Name Housekeeping.costperroom: '1.c Model Simulated data'!#REF!
Name housekeepingcostperroom: 'ModelwithRP$150LCF$50'!$H$21
Name housekeepingcostperroom: 'ModelwithRP$150LCF$70'!$H$21
Name housekeepingcostperroom: 'ModelwithRP$180LCF$50'!$H$21
Name housekeepingcostperroom: 'ModelwithRP$180LCF$70'!$H$21
Name housekeepingcostperroom: '1.c Model Simulated data'!$H$21
Name Late_Cancellation_Fee: #REF!

Sheet 1.a Manager's Page
B3: Stochastic inputs | C3: Desription and assumption
B4: Daily Online Bookings | C4: The number of online reservations per day. The number of online bookings per day is assumed to vary randomly around a central average (mean = 20 for room with price = 180 and mean = 22 for room with price = 150) with moderate fluctuations (standard deviation = 3). Online bookings are influenced by multiple independent factors (day of the week, season, promotions), which makes the Normal distribution appropriate under the Central Limit Theorem.
B5: Daily Cancellations | C5: The number of guests who cancel after booking. Each online booking has a fixed probability (10% for $180 room and nearly 15% for $150 room) of being cancelled. The total number of cancellations is a result of many independent yes/no decisions. Cancellations are best modeled using the Binomial distribution, where each booking has an independent and identical chance of cancellation.
B6: Daily Walk-ins | C6: Guests who arrive without booking. The number of walk-in guests is equally likely to be any integer between 2 and 6 for $180 room and between 3 and 7 for $150 room. Walk-in traffic is treated as equally likely across a defined range. The Discrete Uniform distribution is suitable when each outcome has an equal chance of occurring.
B7: Daily Miscellaneous Expenses | C7: Additional daily operational costs (e.g., supplies, admin). Daily miscellaneous operational costs (e.g., supplies, printing, admin) typically average around $150, but can range between $100 and $200. The most likely value is $150.
B9: Decision variables | C9: Desription and assumption
B10: Room Price | C10: Prices per night per room, set by management, varying between $150 and $180
B11: Late Cancellation Fee | C11: Amount charged per cancelled booking. This can be varied to influence customer behavior or generate revenue. They vary between $50 and $70
B13: Fixed inputs | C13: Desription and assumption
B14: Number of Rooms | C14: The total number of physical rooms available in the motel (25 rooms)
B15: House Keeping Cost per Room | C15: Daily cleaning cost per room that is occupied ($30). Fixed cost applied to every occupied room
B18: CALCULATED VALUES | C18: Desription and assumption
... B23: Daily Total Revenue | C23: Sum of room revenue and cancellation revenue. Daily Total Revenue = Number of Occupied Rooms*Room Price + Daily Cancellations*Late Cancellation Fee
B26: OUTPUT
B27: Total Daily Profit | C27: Final profit of the day. Total Daily Profit = Daily Total Revenue - Daily Operation Cost
B28: Sold Out: Yes/ No | C28: Indicates whether all rooms were fully occupied. “Yes” if Number of Occupied Rooms = Number of Rooms, otherwise "No"

Sheet 1.b Model_Best estimates
G2: INPUTS
B3: CALCULATED VALUES & OUTPUT | C3: values | G3: Stochastic inputs | H3: values
B4: Number of Occupied Rooms | C4: =MIN(H20, (H4 + H6 - H5)) -> 21 | G4: Daily Online Bookings | H4: =IF(H12=180,20,22) -> 20
B5: Showed Up Guests | C5: =H4 + H6 - H5 -> 21 | G5: Daily Cancellations | H5: =IF(H12=180,3,4) -> 3
B6: Overbooked Guests | C6: =MAX((C5 - H20), 0) -> 0 | G6: Daily Walk-ins | H6: =IF(H12=180,4,5) -> 4
B7: Daily Operation Cost | C7: =C4*H21 + C6*H12 + H7 -> 780 | G7: Daily Miscellaneous Expenses | H7: 150
B8: Daily Total Revenue | C8: =C4*H12+H5*H13 -> 3930
G11: Decision variables | H11: values
B12: OUTPUT | G12: Room Price | H12: 180
B13: Total Daily Profit | C13: =C8-C7 -> 3150 | G13: Late Cancellation Fee | H13: 50
B14: Sold Out: Yes/ No | C14: =IF(C4=H20,"Yes","No") -> No
G19: Fixed inputs | H19: values
G20: Number of Rooms | H20: 25
G21: House Keeping Cost per Room | H21: 30

Sheet 1.c Model Simulated data
G2: INPUTS
B3: CALCULATED VALUES & OUTPUT | C3: values | G3: Stochastic inputs | H3: values
B4: Number of Occupied Rooms | C4: =MIN(H20, (H4 + H6 - H5)) -> 21 | G4: Daily Online Bookings | H4: 20 | K4: {=_xlfn.IFS( AND(#REF!=250,#REF!= 5%), VLOOKUP(RAND(), '3. Probability Distributions'!#REF!, 3), AND('1.c Model Simulated data'!#REF!=250, '1.c Model Simulated data'!#REF!=10%), VLOOKUP(RAND(), '3. Probability Distributions'!#REF!, 3), AND('1.c Model Simulated data'!#REF!=275, '1.c Model Simulated data'!#REF!=5%), VLOOKUP(RAND(), '3. Probability Distributions'!#REF!, 3), AND('1.c Model Simulated data'!#REF!=275, '1.c Model Simulated data'!#REF!=10%), VLOOKUP(RAND(), '3. Probability Distributions'!#REF!, 3) )} -> #REF!
B5: Showed Up Guests | C5: =H4 + H6 - H5 -> 21 | G5: Daily Cancellations | H5: 3
B6: Overbooked Guests | C6: =MAX((C5 - H20), 0) -> 0 | G6: Daily Walk-ins | H6: 4
B7: Daily Operation Cost | C7: =C4*H21 + C6*H12 + H7 -> 780 | G7: Daily Miscellaneous Expenses | H7: 150
B8: Daily Total Revenue | C8: =C4*H12+H5*H13 -> 3930
G11: Decision variables
B12: OUTPUT | G12: Room Price | H12: 180
B13: Total Daily Profit | C13: =C8-C7 -> 3150 | G13: Late Cancellation Fee | H13: 50
B14: Sold Out: Yes/ No | C14: =IF(C4=H20,"Yes","No") -> No
G19: Fixed inputs | H19: values
G20: Number of Rooms | H20: 25
G21: House Keeping Cost per Room | H21: 30

Sheet 2.a.1 Scenario for $180 Room
B2: Scenario Summary | I2: Scenario Summary
D3: Current Values: | E3: Best case | F3: Base case | G3: Worst case | K3: Current Values: | L3: Best case | M3: Base case | N3: Worst case
E4: Created by Skylar on 22/5/2025 | F4: Created by Skylar on 22/5/2025 | G4: Created by Skylar on 22/5/2025 | L4: Created by Skylar on 22/5/2025 Modified by Skylar on 22/5/2025 | M4: Created by Skylar on 22/5/2025 Modified by Skylar on 22/5/2025 | N4: Created by Skylar on 22/5/2025 Modified by Skylar on 22/5/2025
B5: Changing Cells: | I5: Changing Cells:
C6: daily.online.reservation | D6: 20 | E6: 23 | F6: 20 | G6: 17 | J6: late.cancellation | K6: 3 | L6: 1 | M6: 3 | N6: 5
B7: Result Cells: | I7: Result Cells:
C8: Total.daily.profit | D8: 3150 | E8: 3600 | F8: 3150 | G8: 2700 | J8: Total.daily.profit | K8: 3150 | L8: 3350 | M8: 3150 | N8: 2950
B14: Scenario Summary | I14: Scenario Summary
D15: Current Values: | E15: Best case | F15: Base case | G15: Worst case | K15: Current Values: | L15: Best case | M15: Base case | N15: Worst case
B17: Changing Cells: | I17: Changing Cells:
C18: walk.ins | D18: 4 | E18: 6 | F18: 4 | G18: 2 | J18: Miscellaneous.expenses | K18: 150 | L18: 120 | M18: 150 | N18: 170
B19: Result Cells: | I19: Result Cells:
C20: Total.daily.profit | D20: 3150 | E20: 3450 | F20: 3150 | G20: 2850 | J20: Total.daily.profit | K20: 3150 | L20: 3180 | M20: 3150 | N20: 3130

Sheet 2.a.2 Scenario for $150 Room
B2: Scenario Summary | I2: Scenario Summary
D3: Current Values: | E3: Best case | F3: Base case | G3: Worst case | K3: Current Values: | L3: Best case | M3: Base case | N3: Worst case
E4: Created by Skylar on 22/5/2025 Modified by Skylar on 22/5/2025 | F4: Created by Skylar on 22/5/2025 Modified by Skylar on 22/5/2025 | G4: Created by Skylar on 22/5/2025 Modified by Skylar on 22/5/2025 | L4: Created by Skylar on 22/5/2025 Modified by Skylar on 22/5/2025 | M4: Created by Skylar on 22/5/2025 Modified by Skylar on 22/5/2025 | N4: Created by Skylar on 22/5/2025 Modified by Skylar on 22/5/2025
B5: Changing Cells: | I5: Changing Cells:
C6: daily.online.reservation | D6: 22 | E6: 25 | F6: 22 | G6: 19 | J6: late.cancellation | K6: 4 | L6: 2 | M6: 4 | N6: 6
B7: Result Cells: | I7: Result Cells:
C8: Total.daily.profit | D8: 2810 | E8: 2900 | F8: 2810 | G8: 2450 | J8: Total.daily.profit | K8: 2810 | L8: 2950 | M8: 2810 | N8: 2670
B14: Scenario Summary | I14: Scenario Summary
D15: Current Values: | E15: Best case | F15: Base case | G15: Worst case | K15: Current Values: | L15: Best case | M15: Base case | N15: Worst case
B17: Changing Cells: | I17: Changing Cells:
C18: walk.ins | D18: 5 | E18: 7 | F18: 5 | G18: 3 | J18: Miscellaneous.expenses | K18: 150 | L18: 120 | M18: 150 | N18: 170
B19: Result Cells: | I19: Result Cells:
C20: Total.daily.profit | D20: 2810 | E20: 3050 | F20: 2810 | G20: 2570 | J20: Total.daily.profit | K20: 2810 | L20: 2840 | M20: 2810 | N20: 2790

Sheet 2.bSummary of Scenario analysis
B2: Scenarios | C2: Best | D2: Base | E2: Worst
B3: $180 Room with $50 Cancellation Fee
A4: changing cell | B4: daily.online.reservation | C4: 23 | D4: 20 | E4: 17
A5: Output result | B5: Total.daily.profit | C5: 3600 | D5: 3150 | E5: 2700
A8: changing cell | B8: late.cancellation | C8: 1 | D8: 3 | E8: 5
A9: Output result | B9: Total.daily.profit | C9: 3350 | D9: 3150 | E9: 2950
A12: changing cell | B12: walk.ins | C12: 6 | D12: 4 | E12: 2
A13: Output result | B13: Total.daily.profit | C13: 3450 | D13: 3150 | E13: 2850
A16: changing cell | B16: Miscellaneous.expenses | C16: 120 | D16: 150 | E16: 170
A17: Output result | B17: Total.daily.profit | C17: 3180 | D17: 3150 | E17: 3130
B19: $150 Room with $50 Cancellation Fee
A20: changing cell | B20: daily.online.reservation | C20: 25 | D20: 22 | E20: 19
A21: Output result | B21: Total.daily.profit | C21: 2900 | D21: 2810 | E21: 2450
A24: changing cell | B24: late.cancellation | C24: 2 | D24: 4 | E24: 6
A25: Output result | B25: Total.daily.profit | C25: 2950 | D25: 2810 | E25: 2670
A28: changing cell | B28: walk.ins | C28: 7 | D28: 5 | E28: 3
A29: Output result | B29: Total.daily.profit | C29: 3050 | D29: 2810 | E29: 2570
A32: changing cell | B32: Miscellaneous.expenses | C32: 120 | D32: 150 | E32: 170
A33: Output result | B33: Total.daily.profit | C33: 2840 | D33: 2810 | E33: 2790

Sheet 3. Probability Distributions
B2: Normal Distribution | J2: Binomial Distribution | R2: Uniform Distribution | Z2: Triangular Distribution
B4: Daily Online Bookings: | C4: Normal | J4: Daily Cancellations: | K4: Binomial | R4: Daily Walk-ins: | S4: Uniform | Z4: Daily Miscellaneous Expenses: | AA4: Triangular
D7: Mean | E7: deviation | L7: n | M7: p | T7: Lower Limit | U7: Upper Limit | AB7: A | AC7: M | AD7: B
C8: Price $180 | D8: 20 | E8: 3 | K8: Price $180 | L8: 20 | M8: 0.1 | S8: $180 | T8: 2 | U8: 6 | AA8: =RAND() -> 0.85141749 | AB8: 100 | AC8: 150 | AD8: 200
C9: Price $150 | D9: 22 | E9: 3 | K9: Price $150 | L9: 22 | M9: 0.15 | S9: $150 | T9: 3 | U9: 7
AD10: =IF(AA8>(AC8-AB8)/(AD8-AB8),AD8-SQRT((1-AA8)*(AD8-AB8)*(AD8-AC8)),AB8+SQRT(AA8*(AC8-AB8)*(AD8-AB8))) -> 172.74358
C11: Daily Online Booking when price is $180 | D11: =RAND() -> 0.22206625 | E11: =MAX(0,_xlfn.NORM.INV(D11,20,3)) -> 17.704299 | K11: Daily Cancellations when price is $180 | L11: =RAND() -> 0.25627303 | M11: =_xlfn.BINOM.INV(L8,M8,L11) -> 1 | S11: Daily Walk-ins for $180 room | T11: =RAND() -> 0.90125853 | U11: =T8+(U8-T8)*T11 -> 5.6050341
C12: Daily Online Booking when price is $150 | D12: =RAND() -> 0.8280109 | E12: =MAX(0,_xlfn.NORM.INV(D12,22,3)) -> 24.839002 | K12: Daily Cancellations when price is $150 | L12: =RAND() -> 0.63689444 | M12: =_xlfn.BINOM.INV(L9,M9,L12) -> 4 | S12: Daily Walk-ins for $150 room | T12: =RAND() -> 0.7903928 | U12: =T9+(U9-T9)*T12 -> 6.1615712

Sheet ModelwithRP$180LCF$50
G2: INPUTS
B3: CALCULATED VALUES & OUTPUT | C3: values | G3: Stochastic inputs | H3: values
B4: Number of Occupied Rooms | C4: =MIN(H20, (H4 + H6 - H5)) -> 22.309334 | G4: Daily Online Bookings | H4: ='3. Probability Distributions'!E11 -> 17.704299 | K4: {=_xlfn.IFS( AND(#REF!=250,#REF!= 5%), VLOOKUP(RAND(), '3. Probability Distributions'!#REF!, 3), AND('ModelwithRP$180LCF$50'!#REF!=250, 'ModelwithRP$180LCF$50'!#REF!=10%), VLOOKUP(RAND(), '3. Probability Distributions'!#REF!, 3), AND('ModelwithRP$180LCF$50'!#REF!=275, 'ModelwithRP$180LCF$50'!#REF!=5%), VLOOKUP(RAND(), '3. Probability Distributions'!#REF!, 3), AND('ModelwithRP$180LCF$50'!#REF!=275, 'ModelwithRP$180LCF$50'!#REF!=10%), VLOOKUP(RAND(), '3. Probability Distributions'!#REF!, 3) )} -> #REF!
B5: Showed Up Guests | C5: =H4 + H6 - H5 -> 22.309334 | G5: Daily Cancellations | H5: ='3. Probability Distributions'!M11 -> 1
B6: Overbooked Guests | C6: =MAX((C5 - H20), 0) -> 0 | G6: Daily Walk-ins | H6: ='3. Probability Distributions'!U11 -> 5.6050341
B7: Daily Operation Cost | C7: =C4*H21 + C6*H12 + H7 -> 842.02358 | G7: Daily Miscellaneous Expenses | H7: ='3. Probability Distributions'!AD10 -> 172.74358
B8: Daily Total Revenue | C8: =C4*H12+H5*H13 -> 4065.68
G11: Decision variables
B12: OUTPUT | G12: Room Price | H12: 180
B13: Total Daily Profit | C13: =C8-C7 -> 3223.6565 | G13: Late Cancellation Fee | H13: 50
B14: Sold Out: Yes/ No | C14: =IF(C4=H20,"Yes","No") -> No
G19: Fixed inputs | H19: values
G20: Number of Rooms | H20: 25
G21: House Keeping Cost per Room | H21: 30

Sheet ModelwithRP$180LCF$70
G2: INPUTS
B3: CALCULATED VALUES & OUTPUT | C3: values | G3: Stochastic inputs | H3: values
B4: Number of Occupied Rooms | C4: =MIN(H20, (H4 + H6 - H5)) -> 22.309334 | G4: Daily Online Bookings | H4: ='3. Probability Distributions'!E11 -> 17.704299 | K4: {=_xlfn.IFS( AND(#REF!=250,#REF!= 5%), VLOOKUP(RAND(), '3. Probability Distributions'!#REF!, 3), AND('ModelwithRP$180LCF$70'!#REF!=250, 'ModelwithRP$180LCF$70'!#REF!=10%), VLOOKUP(RAND(), '3. Probability Distributions'!#REF!, 3), AND('ModelwithRP$180LCF$70'!#REF!=275, 'ModelwithRP$180LCF$70'!#REF!=5%), VLOOKUP(RAND(), '3. Probability Distributions'!#REF!, 3), AND('ModelwithRP$180LCF$70'!#REF!=275, 'ModelwithRP$180LCF$70'!#REF!=10%), VLOOKUP(RAND(), '3. Probability Distributions'!#REF!, 3) )} -> #REF!
B5: Showed Up Guests | C5: =H4 + H6 - H5 -> 22.309334 | G5: Daily Cancellations | H5: ='3. Probability Distributions'!M11 -> 1
B6: Overbooked Guests | C6: =MAX((C5 - H20), 0) -> 0 | G6: Daily Walk-ins | H6: ='3. Probability Distributions'!U11 -> 5.6050341
B7: Daily Operation Cost | C7: =C4*H21 + C6*H12 + H7 -> 842.02358 | G7: Daily Miscellaneous Expenses | H7: ='3. Probability Distributions'!AD10 -> 172.74358
B8: Daily Total Revenue | C8: =C4*H12+H5*H13 -> 4085.68
G11: Decision variables
B12: OUTPUT | G12: Room Price | H12: 180
B13: Total Daily Profit | C13: =C8-C7 -> 3243.6565 | G13: Late Cancellation Fee | H13: 70
B14: Sold Out: Yes/ No | C14: =IF(C4=H20,"Yes","No") -> No
G19: Fixed inputs | H19: values
G20: Number of Rooms | H20: 25
G21: House Keeping Cost per Room | H21: 30

Sheet ModelwithRP$150LCF$50
G2: INPUTS
B3: CALCULATED VALUES & OUTPUT | C3: values | G3: Stochastic inputs | H3: values
B4: Number of Occupied Rooms | C4: =MIN(H20, (H4 + H6 - H5)) -> 25 | G4: Daily Online Bookings | H4: ='3. Probability Distributions'!E12 -> 24.839002 | K4: {=_xlfn.IFS( AND(#REF!=250,#REF!= 5%), VLOOKUP(RAND(), '3. Probability Distributions'!#REF!, 3), AND('ModelwithRP$150LCF$50'!#REF!=250, 'ModelwithRP$150LCF$50'!#REF!=10%), VLOOKUP(RAND(), '3. Probability Distributions'!#REF!, 3), AND('ModelwithRP$150LCF$50'!#REF!=275, 'ModelwithRP$150LCF$50'!#REF!=5%), VLOOKUP(RAND(), '3. Probability Distributions'!#REF!, 3), AND('ModelwithRP$150LCF$50'!#REF!=275, 'ModelwithRP$150LCF$50'!#REF!=10%), VLOOKUP(RAND(), '3. Probability Distributions'!#REF!, 3) )} -> #REF!
B5: Showed Up Guests | C5: =H4 + H6 - H5 -> 27.000574 | G5: Daily Cancellations | H5: ='3. Probability Distributions'!M12 -> 4
B6: Overbooked Guests | C6: =MAX((C5 - H20), 0) -> 2.0005735 | G6: Daily Walk-ins | H6: ='3. Probability Distributions'!U12 -> 6.1615712
B7: Daily Operation Cost | C7: =C4*H21 + C6*H12 + H7 -> 1222.8296 | G7: Daily Miscellaneous Expenses | H7: ='3. Probability Distributions'!AD10 -> 172.74358
B8: Daily Total Revenue | C8: =C4*H12+H5*H13 -> 3950
G11: Decision variables
B12: OUTPUT | G12: Room Price | H12: 150
B13: Total Daily Profit | C13: =C8-C7 -> 2727.1704 | G13: Late Cancellation Fee | H13: 50
B14: Sold Out: Yes/ No | C14: =IF(C4=H20,"Yes","No") -> Yes
G19: Fixed inputs | H19: values
G20: Number of Rooms | H20: 25
G21: House Keeping Cost per Room | H21: 30

Sheet ModelwithRP$150LCF$70
G2: INPUTS
B3: CALCULATED VALUES & OUTPUT | C3: values | G3: Stochastic inputs | H3: values
B4: Number of Occupied Rooms | C4: =MIN(H20, (H4 + H6 - H5)) -> 25 | G4: Daily Online Bookings | H4: ='3. Probability Distributions'!E12 -> 24.839002 | K4: {=_xlfn.IFS( AND(#REF!=250,#REF!= 5%), VLOOKUP(RAND(), '3. Probability Distributions'!#REF!, 3), AND('ModelwithRP$150LCF$70'!#REF!=250, 'ModelwithRP$150LCF$70'!#REF!=10%), VLOOKUP(RAND(), '3. Probability Distributions'!#REF!, 3), AND('ModelwithRP$150LCF$70'!#REF!=275, 'ModelwithRP$150LCF$70'!#REF!=5%), VLOOKUP(RAND(), '3. Probability Distributions'!#REF!, 3), AND('ModelwithRP$150LCF$70'!#REF!=275, 'ModelwithRP$150LCF$70'!#REF!=10%), VLOOKUP(RAND(), '3. Probability Distributions'!#REF!, 3) )} -> #REF!
B5: Showed Up Guests | C5: =H4 + H6 - H5 -> 27.000574 | G5: Daily Cancellations | H5: ='3. Probability Distributions'!M12 -> 4
B6: Overbooked Guests | C6: =MAX((C5 - H20), 0) -> 2.0005735 | G6: Daily Walk-ins | H6: ='3. Probability Distributions'!U12 -> 6.1615712
B7: Daily Operation Cost | C7: =C4*H21 + C6*H12 + H7 -> 1222.8296 | G7: Daily Miscellaneous Expenses | H7: ='3. Probability Distributions'!AD10 -> 172.74358
B8: Daily Total Revenue | C8: =C4*H12+H5*H13 -> 4030
G11: Decision variables
B12: OUTPUT | G12: Room Price | H12: 150
B13: Total Daily Profit | C13: =C8-C7 -> 2807.1704 | G13: Late Cancellation Fee | H13: 70
B14: Sold Out: Yes/ No | C14: =IF(C4=H20,"Yes","No") -> Yes
G19: Fixed inputs | H19: values
G20: Number of Rooms | H20: 25
G21: House Keeping Cost per Room | H21: 30

Sheet 4.Simulation
B2: SIMULATION OF 1,000 TRIALS AT PRICE $180 AND LATE CANCELLATION FEE AT $50 | O2: TRACKING CONVERGENCE OF OUTPUT MEANS | X2: SIMULATION OF 1,000 TRIALS AT PRICE $180 AND LATE CANCELLATION FEE AT $70 | AK2: TRACKING CONVERGENCE OF OUTPUT MEANS | AT2: SIMULATION OF 1,000 TRIALS AT PRICE $150 AND LATE CANCELLATION FEE AT $50 | BG2: TRACKING CONVERGENCE OF OUTPUT MEANS | BP2: SIMULATION OF 1,000 TRIALS AT PRICE $150 AND LATE CANCELLATION FEE AT $70 | CC2: TRACKING CONVERGENCE OF OUTPUT MEANS
B4: Simulation trial | C4: Daily Online Bookings | D4: Daily Cancellations | E4: Daily Wak-ins | F4: Daily Miscellaneous Expenses | G4: Number of Occupied Rooms | H4: Showed Up Guests | I4: Overbooked Guests | J4: Daily Operation Cost | K4: Daily Total Revenue | L4: Total Daily Profit | M4: Sold Out | O4: Mean Number of Occupied Rooms | P4: Mean Showed Up Guests | Q4: Mean Overbooked Guests | R4: Mean Daily Operation Cost | S4: Mean Daily Total Revenue | T4: Mean Daily Profit | X4: Simulation trial | Y4: Daily Online Bookings | Z4: Daily Cancellations | AA4: Daily Wak-ins | AB4: Daily Miscellaneous Expenses | AC4: Number of Occupied Rooms | AD4: Showed Up Guests | AE4: Overbooked Guests | AF4: Daily Operation Cost | AG4: Daily Total Revenue | AH4: Total Daily Profit | AI4: Sold Out | AK4: Mean Number of Occupied Rooms | AL4: Mean Showed Up Guests | AM4: Mean Overbooked Guests | AN4: Mean Daily Operation Cost | AO4: Mean Daily Total Revenue | AP4: Mean Daily Profit | AT4: Simulation trial | AU4: Daily Online Bookings | AV4: Daily Cancellations | AW4: Daily Wak-ins | AX4: Daily Miscellaneous Expenses | AY4: Number of Occupied Rooms | AZ4: Showed Up Guests | BA4: Overbooked Guests | BB4: Daily Operation Cost | BC4: Daily Total Revenue | BD4: Total Daily Profit | BE4: Sold Out | BG4: Mean Number of Occupied Rooms | BH4: Mean Showed Up Guests | BI4: Mean Overbooked Guests | BJ4: Mean Daily Operation Cost | BK4: Mean Daily Total Revenue | BL4: Mean Daily Profit | BP4: Simulation trial | BQ4: Daily Online Bookings | BR4: Daily Cancellations | BS4: Daily Wak-ins | BT4: Daily Miscellaneous Expenses | BU4: Number of Occupied Rooms | BV4: Showed Up Guests | BW4: Overbooked Guests | BX4: Daily Operation Cost | BY4: Daily Total Revenue | BZ4: Total Daily Profit | CA4: Sold Out | CC4: Mean Number of Occupied Rooms | CD4: Mean Showed Up Guests | CE4: Mean Overbooked Guests | CF4: Mean Daily Operation Cost | CG4: Mean Daily Total Revenue | CH4: Mean Daily Profit
C5: ='ModelwithRP$180LCF$50'!daily.online.reservation -> 17.704299 | D5: ='ModelwithRP$180LCF$50'!late.cancellation -> 1 | E5: ='ModelwithRP$180LCF$50'!walk.ins -> 5.6050341 | F5: ='ModelwithRP$180LCF$50'!Miscellaneous.expenses -> 172.74358 | G5: ='ModelwithRP$180LCF$50'!numberof.roomsoccupied -> 22.309334 | H5: ='ModelwithRP$180LCF$50'!showedup.guests -> 22.309334 | I5: ='ModelwithRP$180LCF$50'!overbooked.guests -> 0 | J5: ='ModelwithRP$180LCF$50'!operationcost -> 842.02358 | K5: ='ModelwithRP$180LCF$50'!dailyrevenue -> 4065.68 | L5: ='ModelwithRP$180LCF$50'!Total.daily.profit -> 3223.6565 | M5: ='ModelwithRP$180LCF$50'!C14 -> No | Y5: ='ModelwithRP$180LCF$70'!daily.online.reservation -> 17.704299 | Z5: ='ModelwithRP$180LCF$70'!late.cancellation -> 1 | AA5: ='ModelwithRP$180LCF$70'!walk.ins -> 5.6050341 | AB5: ='ModelwithRP$180LCF$70'!Miscellaneous.expenses -> 172.74358 | AC5: ='ModelwithRP$180LCF$70'!numberof.roomsoccupied -> 22.309334 | AD5: ='ModelwithRP$180LCF$70'!showedup.guests -> 22.309334 | AE5: ='ModelwithRP$180LCF$70'!overbooked.guests -> 0 | AF5: ='ModelwithRP$180LCF$70'!operationcost -> 842.02358 | AG5: ='ModelwithRP$180LCF$70'!dailyrevenue -> 4085.68 | AH5: ='ModelwithRP$180LCF$70'!Total.daily.profit -> 3243.6565 | AI5: ='ModelwithRP$180LCF$70'!C14 -> No | AU5: ='ModelwithRP$150LCF$50'!daily.online.reservation -> 24.839002 | AV5: ='ModelwithRP$150LCF$50'!late.cancellation -> 4 | AW5: ='ModelwithRP$150LCF$50'!walk.ins -> 6.1615712 | AX5: ='ModelwithRP$150LCF$50'!Miscellaneous.expenses -> 172.74358 | AY5: ='ModelwithRP$150LCF$50'!numberof.roomsoccupied -> 25 | AZ5: ='ModelwithRP$150LCF$50'!showedup.guests -> 27.000574 | BA5: ='ModelwithRP$150LCF$50'!overbooked.guests -> 2.0005735 | BB5: ='ModelwithRP$150LCF$50'!operationcost -> 1222.8296 | BC5: ='ModelwithRP$150LCF$50'!dailyrevenue -> 3950 | BD5: ='ModelwithRP$150LCF$50'!Total.daily.profit -> 2727.1704 | BE5: ='ModelwithRP$150LCF$50'!C14 -> Yes | BQ5: ='ModelwithRP$150LCF$70'!daily.online.reservation -> 24.839002 | BR5: ='ModelwithRP$150LCF$70'!late.cancellation -> 4 | BS5: ='ModelwithRP$150LCF$70'!walk.ins -> 6.1615712 | BT5: ='ModelwithRP$150LCF$70'!Miscellaneous.expenses -> 172.74358 | BU5: ='ModelwithRP$150LCF$70'!numberof.roomsoccupied -> 25 | BV5: ='ModelwithRP$150LCF$70'!showedup.guests -> 27.000574 | BW5: ='ModelwithRP$150LCF$70'!overbooked.guests -> 2.0005735 | BX5: ='ModelwithRP$150LCF$70'!operationcost -> 1222.8296 | BY5: ='ModelwithRP$150LCF$70'!dailyrevenue -> 4030 | BZ5: ='ModelwithRP$150LCF$70'!Total.daily.profit -> 2807.1704 | CA5: ='ModelwithRP$150LCF$70'!C14 -> Yes
B6: 1 | C6: 23.609733 | D6: 2 | E6: 4.5925 | F6: 173.86615 | G6: 25 | H6: 26.202233 | I6: 1.2022329 | J6: 1140.2681 | K6: 4600 | L6: 3459.7319 | M6: Yes | O6: =AVERAGE(G$6:G6) -> 25 | P6: =AVERAGE(H$6:H6) -> 26.202233 | Q6: =AVERAGE(I$6:I6) -> 1.2022329 | R6: =AVERAGE(J$6:J6) -> 1140.2681 | S6: =AVERAGE(K$6:K6) -> 4600 | T6: =AVERAGE(L$6:L6) -> 3459.7319 | X6: 1 | Y6: 17.062489 | Z6: 2 | AA6: 4.1337082 | AB6: 136.22045 | AC6: 19.196197 | AD6: 19.196197 | AE6: 0 | AF6: 712.10636 | AG6: 3595.3155 | AH6: 2883.2091 | AI6: No | AK6: =AVERAGE(AC$6:AC6) -> 19.196197 | AL6: =AVERAGE(AD$6:AD6) -> 19.196197 | AM6: =AVERAGE(AE$6:AE6) -> 0 | AN6: =AVERAGE(AF$6:AF6) -> 712.10636 | AO6: =AVERAGE(AG$6:AG6) -> 3595.3155 | AP6: =AVERAGE(AH$6:AH6) -> 2883.2091 | AT6: 1 | AU6: 21.535584 | AV6: 3 | AW6: 6.0577265 | AX6: 165.33331 | AY6: 24.593311 | AZ6: 24.593311 | BA6: 0 | BB6: 903.13263 | BC6: 3838.9966 | BD6: 2935.864 | BE6: No | BG6: =AVERAGE(AY$6:AY6) -> 24.593311 | BH6: =AVERAGE(AZ$6:AZ6) -> 24.593311 | BI6: =AVERAGE(BA$6:BA6) -> 0 | BJ6: =AVERAGE(BB$6:BB6) -> 903.13263 | BK6: =AVERAGE(BC$6:BC6) -> 3838.9966 | BL6: =AVERAGE(BD$6:BD6) -> 2935.864 | BP6: 1 | BQ6: 23.130384 | BR6: 3 | BS6: 5.4187314 | BT6: 147.82552 | BU6: 25 | BV6: 25.549115 | BW6: 0.5491154 | BX6: 980.19284 | BY6: 3960 | BZ6: 2979.8072 | CA6: Yes | CC6: =AVERAGE(BU$6:BU6) -> 25 | CD6: =AVERAGE(BV$6:BV6) -> 25.549115 | CE6: =AVERAGE(BW$6:BW6) -> 0.5491154 | CF6: =AVERAGE(BX$6:BX6) -> 980.19284 | CG6: =AVERAGE(BY$6:BY6) -> 3960 | CH6: =AVERAGE(BZ$6:BZ6) -> 2979.8072
B7: 2 | C7: 19.562261 | D7: 1 | E7: 2.1442438 | F7: 153.69332 | G7: 20.706505 | H7: 20.706505 | I7: 0 | J7: 774.88845 | K7: 3777.1708 | L7: 3002.2824 | M7: No | O7: =AVERAGE(G$6:G7) -> 22.853252 | P7: =AVERAGE(H$6:H7) -> 23.454369 | Q7: =AVERAGE(I$6:I7) -> 0.60111645 | R7: =AVERAGE(J$6:J7) -> 957.57826 | S7: =AVERAGE(K$6:K7) -> 4188.5854 | T7: =AVERAGE(L$6:L7) -> 3231.0071 | X7: 2 | Y7: 19.066284 | Z7: 3 | AA7: 3.1767236 | AB7: 167.32259 | AC7: 19.243008 | AD7: 19.243008 | AE7: 0 | AF7: 744.61283 | AG7: 3673.7415 | AH7: 2929.1286 | AI7: No | AK7: =AVERAGE(AC$6:AC7) -> 19.219603 | AL7: =AVERAGE(AD$6:AD7) -> 19.219603 | AM7: =AVERAGE(AE$6:AE7) -> 0 | AN7: =AVERAGE(AF$6:AF7) -> 728.3596 | AO7: =AVERAGE(AG$6:AG7) -> 3634.5285 | AP7: =AVERAGE(AH$6:AH7) -> 2906.1689 | AT7: 2 | AU7: 16.36719 | AV7: 1 | AW7: 5.3682152 | AX7: 159.09789 | AY7: 20.735405 | AZ7: 20.735405 | BA7: 0 | BB7: 781.16004 | BC7: 3160.3107 | BD7: 2379.1507 | BE7: No | BG7: =AVERAGE(AY$6:AY7) -> 22.664358 | BH7: =AVERAGE(AZ$6:AZ7) -> 22.664358 | BI7: =AVERAGE(BA$6:BA7) -> 0 | BJ7: =AVERAGE(BB$6:BB7) -> 842.14633 | BK7: =AVERAGE(BC$6:BC7) -> 3499.6537 | BL7: =AVERAGE(BD$6:BD7) -> 2657.5073 | BP7: 2 | BQ7: 22.01865 | BR7: 0 | BS7: 4.7214475 | BT7: 161.08341 | BU7: 25 | BV7: 26.740098 | BW7: 1.7400976 | BX7: 1172.0981 | BY7: 3750 | BZ7: 2577.9019 | CA7: Yes | CC7: =AVERAGE(BU$6:BU7) -> 25 | CD7: =AVERAGE(BV$6:BV7) -> 26.144607 | CE7: =AVERAGE(BW$6:BW7) -> 1.1446065 | CF7: =AVERAGE(BX$6:BX7) -> 1076.1454 | CG7: =AVERAGE(BY$6:BY7) -> 3855 | CH7: =AVERAGE(BZ$6:BZ7) -> 2778.8546
B8: 3 | C8: 17.374513 | D8: 2 | E8: 3.2445209 | F8: 110.78641 | G8: 18.619034 | H8: 18.619034 | I8: 0 | J8: 669.35743 | K8: 3451.4261 | L8: 2782.0687 | M8: No | O8: =AVERAGE(G$6:G8) -> 21.441846 | P8: =AVERAGE(H$6:H8) -> 21.84259 | Q8: =AVERAGE(I$6:I8) -> 0.4007443 | R8: =AVERAGE(J$6:J8) -> 861.50465 | S8: =AVERAGE(K$6:K8) -> 3942.8656 | T8: =AVERAGE(L$6:L8) -> 3081.361 | X8: 3 | Y8: 21.83871 | Z8: 4 | AA8: 2.8784934 | AB8: 130.62664 | AC8: 20.717203 | AD8: 20.717203 | AE8: 0 | AF8: 752.14272 | AG8: 4009.0965 | AH8: 3256.9538 | AI8: No | AK8: =AVERAGE(AC$6:AC8) -> 19.718803 | AL8: =AVERAGE(AD$6:AD8) -> 19.718803 | AM8: =AVERAGE(AE$6:AE8) -> 0 | AN8: =AVERAGE(AF$6:AF8) -> 736.28731 | AO8: =AVERAGE(AG$6:AG8) -> 3759.3845 | AP8: =AVERAGE(AH$6:AH8) -> 3023.0972 | AT8: 3 | AU8: 20.956767 | AV8: 3 | AW8: 6.4766475 | AX8: 131.51279 | AY8: 24.433414 | AZ8: 24.433414 | BA8: 0 | BB8: 864.51521 | BC8: 3815.0121 | BD8: 2950.4969 | BE8: No | BG8: =AVERAGE(AY$6:AY8) -> 23.254043 | BH8: =AVERAGE(AZ$6:AZ8) -> 23.254043 | BI8: =AVERAGE(BA$6:BA8) -> 0 | BJ8: =AVERAGE(BB$6:BB8) -> 849.60262 | BK8: =AVERAGE(BC$6:BC8) -> 3604.7731 | BL8: =AVERAGE(BD$6:BD8) -> 2755.1705 | BP8: 3 | BQ8: 19.272023 | BR8: 1 | BS8: 4.224974 | BT8: 136.11623 | BU8: 22.496997 | BV8: 22.496997 | BW8: 0 | BX8: 811.02614 | BY8: 3444.5495 | BZ8: 2633.5234 | CA8: No | CC8: =AVERAGE(BU$6:BU8) -> 24.165666 | CD8: =AVERAGE(BV$6:BV8) -> 24.928737 | CE8: =AVERAGE(BW$6:BW8) -> 0.76307101 | CF8: =AVERAGE(BX$6:BX8) -> 987.77234 | CG8: =AVERAGE(BY$6:BY8) -> 3718.1832 | CH8: =AVERAGE(BZ$6:BZ8) -> 2730.4108
B9: 4 | C9: 21.497152 | D9: 3 | E9: 5.8866812 | F9: 191.49564 | G9: 24.383833 | H9: 24.383833 | I9: 0 | J9: 923.01063 | K9: 4539.09 | L9: 3616.0793 | M9: No | O9: =AVERAGE(G$6:G9) -> 22.177343 | P9: =AVERAGE(H$6:H9) -> 22.477901 | Q9: =AVERAGE(I$6:I9) -> 0.30055822 | R9: =AVERAGE(J$6:J9) -> 876.88115 | S9: =AVERAGE(K$6:K9) -> 4091.9217 | T9: =AVERAGE(L$6:L9) -> 3215.0406 | X9: 4 | Y9: 20.34171 | Z9: 0 | AA9: 3.6809129 | AB9: 156.8529 | AC9: 24.022623 | AD9: 24.022623 | AE9: 0 | AF9: 877.53159 | AG9: 4324.0721 | AH9: 3446.5406 | AI9: No | AK9: =AVERAGE(AC$6:AC9) -> 20.794758 | AL9: =AVERAGE(AD$6:AD9) -> 20.794758 | AM9: =AVERAGE(AE$6:AE9) -> 0 | AN9: =AVERAGE(AF$6:AF9) -> 771.59838 | AO9: =AVERAGE(AG$6:AG9) -> 3900.5564 | AP9: =AVERAGE(AH$6:AH9) -> 3128.958 | AT9: 4 | AU9: 24.997613 | AV9: 5 | AW9: 4.5530657 | AX9: 154.28949 | AY9: 24.550678 | AZ9: 24.550678 | BA9: 0 | BB9: 890.80983 | BC9: 3932.6017 | BD9: 3041.7919 | BE9: No | BG9: =AVERAGE(AY$6:AY9) -> 23.578202 | BH9: =AVERAGE(AZ$6:AZ9) -> 23.578202 | BI9: =AVERAGE(BA$6:BA9) -> 0 | BJ9: =AVERAGE(BB$6:BB9) -> 859.90443 | BK9: =AVERAGE(BC$6:BC9) -> 3686.7303 | BL9: =AVERAGE(BD$6:BD9) -> 2826.8259 | BP9: 4 | BQ9: 27.270517 | BR9: 4 | BS9: 4.8410849 | BT9: 135.7644 | BU9: 25 | BV9: 28.111602 | BW9: 3.1116017 | BX9: 1352.5047 | BY9: 4030 | BZ9: 2677.4953 | CA9: Yes | CC9: =AVERAGE(BU$6:BU9) -> 24.374249 | CD9: =AVERAGE(BV$6:BV9) -> 25.724453 | CE9: =AVERAGE(BW$6:BW9) -> 1.3502037 | CF9: =AVERAGE(BX$6:BX9) -> 1078.9554 | CG9: =AVERAGE(BY$6:BY9) -> 3796.1374 | CH9: =AVERAGE(BZ$6:BZ9) -> 2717.182
B10: 5 | C10: 16.686166 | D10: 2 | E10: 5.0562225 | F10: 144.49715 | G10: 19.742388 | H10: 19.742388 | I10: 0 | J10: 736.7688 | K10: 3653.6299 | L10: 2916.8611 | M10: No | O10: =AVERAGE(G$6:G10) -> 21.690352 | P10: =AVERAGE(H$6:H10) -> 21.930799 | Q10: =AVERAGE(I$6:I10) -> 0.24044658 | R10: =AVERAGE(J$6:J10) -> 848.85868 | S10: =AVERAGE(K$6:K10) -> 4004.2634 | T10: =AVERAGE(L$6:L10) -> 3155.4047 | X10: 5 | Y10: 15.07239 | Z10: 3 | AA10: 4.5730298 | AB10: 153.26648 | AC10: 16.64542 | AD10: 16.64542 | AE10: 0 | AF10: 652.62908 | AG10: 3206.1756 | AH10: 2553.5465 | AI10: No | AK10: =AVERAGE(AC$6:AC10) -> 19.96489 | AL10: =AVERAGE(AD$6:AD10) -> 19.96489 | AM10: =AVERAGE(AE$6:AE10) -> 0 | AN10: =AVERAGE(AF$6:AF10) -> 747.80452 | AO10: =AVERAGE(AG$6:AG10) -> 3761.6802 | AP10: =AVERAGE(AH$6:AH10) -> 3013.8757 | AT10: 5 | AU10: 22.952003 | AV10: 5 | AW10: 6.7128407 | AX10: 127.43702 | AY10: 24.664844 | AZ10: 24.664844 | BA10: 0 | BB10: 867.38233 | BC10: 3949.7266 | BD10: 3082.3442 | BE10: No | BG10: =AVERAGE(AY$6:AY10) -> 23.79553 | BH10: =AVERAGE(AZ$6:AZ10) -> 23.79553 | BI10: =AVERAGE(BA$6:BA10) -> 0 | BJ10: =AVERAGE(BB$6:BB10) -> 861.40001 | BK10: =AVERAGE(BC$6:BC10) -> 3739.3295 | BL10: =AVERAGE(BD$6:BD10) -> 2877.9295 | BP10: 5 | BQ10: 19.82273 | BR10: 3 | BS10: 5.685242 | BT10: 133.2333 | BU10: 22.507972 | BV10: 22.507972 | BW10: 0 | BX10: 808.47246 | BY10: 3586.1958 | BZ10: 2777.7233 | CA10: No | CC10: =AVERAGE(BU$6:BU10) -> 24.000994 | CD10: =AVERAGE(BV$6:BV10) -> 25.081157 | CE10: =AVERAGE(BW$6:BW10) -> 1.080163 | CF10: =AVERAGE(BX$6:BX10) -> 1024.8588 | CG10: =AVERAGE(BY$6:BY10) -> 3754.1491 | CH10: =AVERAGE(BZ$6:BZ10) -> 2729.2902
B11: 6 | C11: 17.318287 | D11: 4 | E11: 2.5419542 | F11: 175.17943 | G11: 15.860242 | H11: 15.860242 | I11: 0 | J11: 650.98668 | K11: 3054.8435 | L11: 2403.8568 | M11: No | O11: =AVERAGE(G$6:G11) -> 20.718667 | P11: =AVERAGE(H$6:H11) -> 20.919039 | Q11: =AVERAGE(I$6:I11) -> 0.20037215 | R11: =AVERAGE(J$6:J11) -> 815.88001 | S11: =AVERAGE(K$6:K11) -> 3846.0267 | T11: =AVERAGE(L$6:L11) -> 3030.1467 | X11: 6 | Y11: 25.652339 | Z11: 2 | AA11: 4.9434567 | AB11: 176.70183 | AC11: 25 | AD11: 28.595796 | AE11: 3.5957958 | AF11: 1573.9451 | AG11: 4640 | AH11: 3066.0549 | AI11: Yes | AK11: =AVERAGE(AC$6:AC11) -> 20.804075 | AL11: =AVERAGE(AD$6:AD11) -> 21.403375 | AM11: =AVERAGE(AE$6:AE11) -> 0.5992993 | AN11: =AVERAGE(AF$6:AF11) -> 885.49461 | AO11: =AVERAGE(AG$6:AG11) -> 3908.0669 | AP11: =AVERAGE(AH$6:AH11) -> 3022.5723 | AT11: 6 | AU11: 21.462906 | AV11: 3 | AW11: 3.1290548 | AX11: 163.21906 | AY11: 21.591961 | AZ11: 21.591961 | BA11: 0 | BB11: 810.97789 | BC11: 3388.7941 | BD11: 2577.8162 | BE11: No | BG11: =AVERAGE(AY$6:AY11) -> 23.428269 | BH11: =AVERAGE(AZ$6:AZ11) -> 23.428269 | BI11: =AVERAGE(BA$6:BA11) -> 0 | BJ11: =AVERAGE(BB$6:BB11) -> 852.99632 | BK11: =AVERAGE(BC$6:BC11) -> 3680.907 | BL11: =AVERAGE(BD$6:BD11) -> 2827.9107 | BP11: 6 | BQ11: 23.53607 | BR11: 6 | BS11: 4.78659 | BT11: 131.65969 | BU11: 22.32266 | BV11: 22.32266 | BW11: 0 | BX11: 801.33948 | BY11: 3768.399 | BZ11: 2967.0595 | CA11: No | CC11: =AVERAGE(BU$6:BU11) -> 23.721271 | CD11: =AVERAGE(BV$6:BV11) -> 24.621407 | CE11: =AVERAGE(BW$6:BW11) -> 0.90013579 | CF11: =AVERAGE(BX$6:BX11) -> 987.60561 | CG11: =AVERAGE(BY$6:BY11) -> 3756.524 | CH11: =AVERAGE(BZ$6:BZ11) -> 2768.9184
B12: 7 | C12: 18.824905 | D12: 2 | E12: 4.0253993 | F12: 129.04231 | G12: 20.850304 | H12: 20.850304 | I12: 0 | J12: 754.55143 | K12: 3853.0547 | L12: 3098.5033 | M12: No | O12: =AVERAGE(G$6:G12) -> 20.737472 | P12: =AVERAGE(H$6:H12) -> 20.90922 | Q12: =AVERAGE(I$6:I12) -> 0.17174756 | R12: =AVERAGE(J$6:J12) -> 807.11878 | S12: =AVERAGE(K$6:K12) -> 3847.0307 | T12: =AVERAGE(L$6:L12) -> 3039.9119 | X12: 7 | Y12: 20.340701 | Z12: 2 | AA12: 2.5059013 | AB12: 137.03795 | AC12: 20.846602 | AD12: 20.846602 | AE12: 0 | AF12: 762.43602 | AG12: 3892.3884 | AH12: 3129.9524 | AI12: No | AK12: =AVERAGE(AC$6:AC12) -> 20.81015 | AL12: =AVERAGE(AD$6:AD12) -> 21.323836 | AM12: =AVERAGE(AE$6:AE12) -> 0.51368511 | AN12: =AVERAGE(AF$6:AF12) -> 867.91481 | AO12: =AVERAGE(AG$6:AG12) -> 3905.8271 | AP12: =AVERAGE(AH$6:AH12) -> 3037.9123 | AT12: 7 | AU12: 16.701695 | AV12: 5 | AW12: 3.4010247 | AX12: 127.69622 | AY12: 15.10272 | AZ12: 15.10272 | BA12: 0 | BB12: 580.77781 | BC12: 2515.408 | BD12: 1934.6302 | BE12: No | BG12: =AVERAGE(AY$6:AY12) -> 22.238905 | BH12: =AVERAGE(AZ$6:AZ12) -> 22.238905 | BI12: =AVERAGE(BA$6:BA12) -> 0 | BJ12: =AVERAGE(BB$6:BB12) -> 814.10796 | BK12: =AVERAGE(BC$6:BC12) -> 3514.4071 | BL12: =AVERAGE(BD$6:BD12) -> 2700.2992 | BP12: 7 | BQ12: 21.5192 | BR12: 3 | BS12: 5.7766591 | BT12: 173.67404 | BU12: 24.295859 | BV12: 24.295859 | BW12: 0 | BX12: 902.54982 | BY12: 3854.3789 | BZ12: 2951.8291 | CA12: No | CC12: =AVERAGE(BU$6:BU12) -> 23.803355 | CD12: =AVERAGE(BV$6:BV12) -> 24.5749 | CE12: =AVERAGE(BW$6:BW12) -> 0.77154496 | CF12: =AVERAGE(BX$6:BX12) -> 975.45478 | CG12: =AVERAGE(BY$6:BY12) -> 3770.5033 | CH12: =AVERAGE(BZ$6:BZ12) -> 2795.0485
B13: 8 | C13: 19.848826 | D13: 5 | E13: 5.3323501 | F13: 139.00161 | G13: 20.181176 | H13: 20.181176 | I13: 0 | J13: 744.43688 | K13: 3882.6117 | L13: 3138.1748 | M13: No | O13: =AVERAGE(G$6:G13) -> 20.667935 | P13: =AVERAGE(H$6:H13) -> 20.818214 | Q13: =AVERAGE(I$6:I13) -> 0.15027911 | R13: =AVERAGE(J$6:J13) -> 799.28355 | S13: =AVERAGE(K$6:K13) -> 3851.4783 | T13: =AVERAGE(L$6:L13) -> 3052.1948 | X13: 8 | Y13: 15.90688 | Z13: 0 | AA13: 3.9324702 | AB13: 142.53551 | AC13: 19.83935 | AD13: 19.83935 | AE13: 0 | AF13: 737.71601 | AG13: 3571.083 | AH13: 2833.367 | AI13: No | AK13: =AVERAGE(AC$6:AC13) -> 20.6888 | AL13: =AVERAGE(AD$6:AD13) -> 21.138275 | AM13: =AVERAGE(AE$6:AE13) -> 0.44947447 | AN13: =AVERAGE(AF$6:AF13) -> 851.63996 | AO13: =AVERAGE(AG$6:AG13) -> 3863.9841 | AP13: =AVERAGE(AH$6:AH13) -> 3012.3441 | AT13: 8 | AU13: 19.87632 | AV13: 3 | AW13: 5.7675132 | AX13: 168.19454 | AY13: 22.643833 | AZ13: 22.643833 | BA13: 0 | BB13: 847.50954 | BC13: 3546.575 | BD13: 2699.0654 | BE13: No | BG13: =AVERAGE(AY$6:AY13) -> 22.289521 | BH13: =AVERAGE(AZ$6:AZ13) -> 22.289521 | BI13: =AVERAGE(BA$6:BA13) -> 0 | BJ13: =AVERAGE(BB$6:BB13) -> 818.28316 | BK13: =AVERAGE(BC$6:BC13) -> 3518.4281 | BL13: =AVERAGE(BD$6:BD13) -> 2700.1449 | BP13: 8 | BQ13: 16.821026 | BR13: 2 | BS13: 5.7789873 | BT13: 143.85023 | BU13: 20.600014 | BV13: 20.600014 | BW13: 0 | BX13: 761.85064 | BY13: 3230.0021 | BZ13: 2468.1514 | CA13: No | CC13: =AVERAGE(BU$6:BU13) -> 23.402938 | CD13: =AVERAGE(BV$6:BV13) -> 24.07804 | CE13: =AVERAGE(BW$6:BW13) -> 0.67510184 | CF13: =AVERAGE(BX$6:BX13) -> 948.75426 | CG13: =AVERAGE(BY$6:BY13) -> 3702.9407 | CH13: =AVERAGE(BZ$6:BZ13) -> 2754.1864
B14: 9 | C14: 16.750669 | D14: 0 | E14: 3.3819419 | F14: 179.07149 | G14: 20.132611 | H14: 20.132611 | I14: 0 | J14: 783.04983 | K14: 3623.87 | L14: 2840.8202 | M14: No | O14: =AVERAGE(G$6:G14) -> 20.608455 | P14: =AVERAGE(H$6:H14) -> 20.742036 | Q14: =AVERAGE(I$6:I14) -> 0.13358143 | R14: =AVERAGE(J$6:J14) -> 797.4798 | S14: =AVERAGE(K$6:K14) -> 3826.1885 | T14: =AVERAGE(L$6:L14) -> 3028.7087 | X14: 9 | Y14: 21.26755 | Z14: 1 | AA14: 3.8062011 | AB14: 140.19866 | AC14: 24.073751 | AD14: 24.073751 | AE14: 0 | AF14: 862.41118 | AG14: 4403.2751 | AH14: 3540.8639 | AI14: No | AK14: =AVERAGE(AC$6:AC14) -> 21.064906 | AL14: =AVERAGE(AD$6:AD14) -> 21.464439 | AM14: =AVERAGE(AE$6:AE14) -> 0.39953287 | AN14: =AVERAGE(AF$6:AF14) -> 852.83676 | AO14: =AVERAGE(AG$6:AG14) -> 3923.9053 | AP14: =AVERAGE(AH$6:AH14) -> 3071.0685 | AT14: 9 | AU14: 20.946105 | AV14: 4 | AW14: 6.8445992 | AX14: 155.59712 | AY14: 23.790704 | AZ14: 23.790704 | BA14: 0 | BB14: 869.31825 | BC14: 3768.6056 | BD14: 2899.2874 | BE14: No | BG14: =AVERAGE(AY$6:AY14) -> 22.456319 | BH14: =AVERAGE(AZ$6:AZ14) -> 22.456319 | BI14: =AVERAGE(BA$6:BA14) -> 0 | BJ14: =AVERAGE(BB$6:BB14) -> 823.95373 | BK14: =AVERAGE(BC$6:BC14) -> 3546.2256 | BL14: =AVERAGE(BD$6:BD14) -> 2722.2719 | BP14: 9 | BQ14: 26.073606 | BR14: 5 | BS14: 4.3010239 | BT14: 147.33087 | BU14: 25 | BV14: 25.37463 | BW14: 0.37463006 | BX14: 953.52538 | BY14: 4100 | BZ14: 3146.4746 | CA14: Yes | CC14: =AVERAGE(BU$6:BU14) -> 23.580389 | CD14: =AVERAGE(BV$6:BV14) -> 24.222105 | CE14: =AVERAGE(BW$6:BW14) -> 0.64171609 | CF14: =AVERAGE(BX$6:BX14) -> 949.28439 | CG14: =AVERAGE(BY$6:BY14) -> 3747.0584 | CH14: =AVERAGE(BZ$6:BZ14) -> 2797.774
B15: 10 | C15: 24.773388 | D15: 1 | E15: 2.6761216 | F15: 149.64392 | G15: 25 | H15: 26.449509 | I15: 1.4495094 | J15: 1160.5556 | K15: 4550 | L15: 3389.4444 | M15: Yes | O15: =AVERAGE(G$6:G15) -> 21.047609 | P15: =AVERAGE(H$6:H15) -> 21.312784 | Q15: =AVERAGE(I$6:I15) -> 0.26517423 | R15: =AVERAGE(J$6:J15) -> 833.78738 | S15: =AVERAGE(K$6:K15) -> 3898.5697 | T15: =AVERAGE(L$6:L15) -> 3064.7823 | X15: 10 | Y15: 18.741278 | Z15: 2 | AA15: 3.009597 | AB15: 184.24559 | AC15: 19.750875 | AD15: 19.750875 | AE15: 0 | AF15: 776.77185 | AG15: 3695.1575 | AH15: 2918.3857 | AI15: No | AK15: =AVERAGE(AC$6:AC15) -> 20.933503 | AL15: =AVERAGE(AD$6:AD15) -> 21.293083 | AM15: =AVERAGE(AE$6:AE15) -> 0.35957958 | AN15: =AVERAGE(AF$6:AF15) -> 845.23027 | AO15: =AVERAGE(AG$6:AG15) -> 3901.0305 | AP15: =AVERAGE(AH$6:AH15) -> 3055.8003 | AT15: 10 | AU15: 21.707426 | AV15: 3 | AW15: 5.9758334 | AX15: 174.53359 | AY15: 24.683259 | AZ15: 24.683259 | BA15: 0 | BB15: 915.03138 | BC15: 3852.4889 | BD15: 2937.4575 | BE15: No | BG15: =AVERAGE(AY$6:AY15) -> 22.679013 | BH15: =AVERAGE(AZ$6:AZ15) -> 22.679013 | BI15: =AVERAGE(BA$6:BA15) -> 0 | BJ15: =AVERAGE(BB$6:BB15) -> 833.06149 | BK15: =AVERAGE(BC$6:BC15) -> 3576.8519 | BL15: =AVERAGE(BD$6:BD15) -> 2743.7904 | BP15: 10 | BQ15: 22.331765 | BR15: 4 | BS15: 4.5049896 | BT15: 154.7539 | BU15: 22.836754 | BV15: 22.836754 | BW15: 0 | BX15: 839.85652 | BY15: 3705.5131 | BZ15: 2865.6566 | CA15: No | CC15: =AVERAGE(BU$6:BU15) -> 23.506026 | CD15: =AVERAGE(BV$6:BV15) -> 24.08357 | CE15: =AVERAGE(BW$6:BW15) -> 0.57754448 | CF15: =AVERAGE(BX$6:BX15) -> 938.3416 | CG15: =AVERAGE(BY$6:BY15) -> 3742.9038 | CH15: =AVERAGE(BZ$6:BZ15) -> 2804.5622
B16: 11 | C16: 16.821229 | D16: 1 | E16: 2.6573988 | F16: 170.19801 | G16: 18.478628 | H16: 18.478628 | I16: 0 | J16: 724.55686 | K16: 3376.1531 | L16: 2651.5962 | M16: No | O16: =AVERAGE(G$6:G16) -> 20.814066 | P16: =AVERAGE(H$6:H16) -> 21.055133 | Q16: =AVERAGE(I$6:I16) -> 0.24106748 | R16: =AVERAGE(J$6:J16) -> 823.85733 | S16: =AVERAGE(K$6:K16) -> 3851.0773 | T16: =AVERAGE(L$6:L16) -> 3027.2199 | X16: 11 | Y16: 21.589681 | Z16: 0 | AA16: 5.0060218 | AB16: 158.21784 | AC16: 25 | AD16: 26.595703 | AE16: 1.5957029 | AF16: 1195.4444 | AG16: 4500 | AH16: 3304.5556 | AI16: Yes | AK16: =AVERAGE(AC$6:AC16) -> 21.303184 | AL16: =AVERAGE(AD$6:AD16) -> 21.775139 | AM16: =AVERAGE(AE$6:AE16) -> 0.47195442 | AN16: =AVERAGE(AF$6:AF16) -> 877.06792 | AO16: =AVERAGE(AG$6:AG16) -> 3955.4823 | AP16: =AVERAGE(AH$6:AH16) -> 3078.4144 | AT16: 11 | AU16: 17.36863 | AV16: 6 | AW16: 6.3920271 | AX16: 127.1153 | AY16: 17.760657 | AZ16: 17.760657 | BA16: 0 | BB16: 659.93501 | BC16: 2964.0986 | BD16: 2304.1635 | BE16: No | BG16: =AVERAGE(AY$6:AY16) -> 22.23189 | BH16: =AVERAGE(AZ$6:AZ16) -> 22.23189 | BI16: =AVERAGE(BA$6:BA16) -> 0 | BJ16: =AVERAGE(BB$6:BB16) -> 817.32272 | BK16: =AVERAGE(BC$6:BC16) -> 3521.1471 | BL16: =AVERAGE(BD$6:BD16) -> 2703.8244 | BP16: 11 | BQ16: 22.713891 | BR16: 3 | BS16: 4.3386834 | BT16: 136.28055 | BU16: 24.052574 | BV16: 24.052574 | BW16: 0 | BX16: 857.85778 | BY16: 3817.8861 | BZ16: 2960.0284 | CA16: No | CC16: =AVERAGE(BU$6:BU16) -> 23.555712 | CD16: =AVERAGE(BV$6:BV16) -> 24.080752 | CE16: =AVERAGE(BW$6:BW16) -> 0.52504044 | CF16: =AVERAGE(BX$6:BX16) -> 931.02489 | CG16: =AVERAGE(BY$6:BY16) -> 3749.7204 | CH16: =AVERAGE(BZ$6:BZ16) -> 2818.6955
B17: 12 | C17: 17.7834 | D17: 0 | E17: 3.1431152 | F17: 126.36579 | G17: 20.926515 | H17: 20.926515 | I17: 0 | J17: 754.16124 | K17: 3766.7727 | L17: 3012.6115 | M17: No | O17: =AVERAGE(G$6:G17) -> 20.823436 | P17: =AVERAGE(H$6:H17) -> 21.044415 | Q17: =AVERAGE(I$6:I17) -> 0.22097853 | R17: =AVERAGE(J$6:J17) -> 818.04933 | S17: =AVERAGE(K$6:K17) -> 3844.0519 | T17: =AVERAGE(L$6:L17) -> 3026.0025 | X17: 12 | Y17: 16.400433 | Z17: 1 | AA17: 3.8756207 | AB17: 149.75869 | AC17: 19.276054 | AD17: 19.276054 | AE17: 0 | AF17: 728.0403 | AG17: 3539.6896 | AH17: 2811.6494 | AI17: No | AK17: =AVERAGE(AC$6:AC17) -> 21.134257 | AL17: =AVERAGE(AD$6:AD17) -> 21.566882 | AM17: =AVERAGE(AE$6:AE17) -> 0.43262489 | AN17: =AVERAGE(AF$6:AF17) -> 864.64895 | AO17: =AVERAGE(AG$6:AG17) -> 3920.8329 | AP17: =AVERAGE(AH$6:AH17) -> 3056.184 | AT17: 12 | AU17: 23.101383 | AV17: 5 | AW17: 6.7569313 | AX17: 164.75086 | AY17: 24.858314 | AZ17: 24.858314 | BA17: 0 | BB17: 910.50028 | BC17: 3978.7471 | BD17: 3068.2468 | BE17: No | BG17: =AVERAGE(AY$6:AY17) -> 22.450758 | BH17: =AVERAGE(AZ$6:AZ17) -> 22.450758 | BI17: =AVERAGE(BA$6:BA17) -> 0 | BJ17: =AVERAGE(BB$6:BB17) -> 825.08752 | BK17: =AVERAGE(BC$6:BC17) -> 3559.2804 | BL17: =AVERAGE(BD$6:BD17) -> 2734.1929 | BP17: 12 | BQ17: 23.458651 | BR17: 5 | BS17: 6.0816815 | BT17: 144.57518 | BU17: 24.540332 | BV17: 24.540332 | BW17: 0 | BX17: 880.78515 | BY17: 4031.0498 | BZ17: 3150.2647 | CA17: No | CC17: =AVERAGE(BU$6:BU17) -> 23.637764 | CD17: =AVERAGE(BV$6:BV17) -> 24.119051 | CE17: =AVERAGE(BW$6:BW17) -> 0.48128707 | CF17: =AVERAGE(BX$6:BX17) -> 926.83824 | CG17: =AVERAGE(BY$6:BY17) -> 3773.1645 | CH17: =AVERAGE(BZ$6:BZ17) -> 2846.3263
... B1005: 1000 | C1005: 18.178156 | D1005: 0 | E1005: 4.0940194 | F1005: 150.30977 | G1005: 22.272175 | H1005: 22.272175 | I1005: 0 | J1005: 818.47502 | K1005: 4008.9915 | L1005: 3190.5165 | M1005: No | O1005: =AVERAGE(G$6:G1005) -> 21.70225 | P1005: =AVERAGE(H$6:H1005) -> 22.054446 | Q1005: =AVERAGE(I$6:I1005) -> 0.35219536 | R1005: =AVERAGE(J$6:J1005) -> 863.60844 | S1005: =AVERAGE(K$6:K1005) -> 4004.8551 | T1005: =AVERAGE(L$6:L1005) -> 3141.2466 | X1005: 1000 | Y1005: 18.698024 | Z1005: 0 | AA1005: 4.9538791 | AB1005: 165.16286 | AC1005: 23.651903 | AD1005: 23.651903 | AE1005: 0 | AF1005: 874.71995 | AG1005: 4257.3425 | AH1005: 3382.6226 | AI1005: No | AK1005: =AVERAGE(AC$6:AC1005) -> 21.597209 | AL1005: =AVERAGE(AD$6:AD1005) -> 21.930784 | AM1005: =AVERAGE(AE$6:AE1005) -> 0.33357489 | AN1005: =AVERAGE(AF$6:AF1005) -> 857.81995 | AO1005: =AVERAGE(AG$6:AG1005) -> 4029.1777 | AP1005: =AVERAGE(AH$6:AH1005) -> 3171.3578 | AT1005: 1000 | AU1005: 10.275818 | AV1005: 6 | AW1005: 3.8603444 | AX1005: 136.08195 | AY1005: 8.1361622 | AZ1005: 8.1361622 | BA1005: 0 | BB1005: 380.16682 | BC1005: 1520.4243 | BD1005: 1140.2575 | BE1005: No | BG1005: =AVERAGE(AY$6:AY1005) -> 22.826901 | BH1005: =AVERAGE(AZ$6:AZ1005) -> 23.66322 | BI1005: =AVERAGE(BA$6:BA1005) -> 0.83631896 | BJ1005: =AVERAGE(BB$6:BB1005) -> 960.15512 | BK1005: =AVERAGE(BC$6:BC1005) -> 3588.8352 | BL1005: =AVERAGE(BD$6:BD1005) -> 2628.6801 | BP1005: 1000 | BQ1005: 17.448492 | BR1005: 3 | BS1005: 3.4695949 | BT1005: 120.12178 | BU1005: 17.918087 | BV1005: 17.918087 | BW1005: 0 | BX1005: 657.66439 | BY1005: 2897.713 | BZ1005: 2240.0486 | CA1005: No | CC1005: =AVERAGE(BU$6:BU1005) -> 22.878139 | CD1005: =AVERAGE(BV$6:BV1005) -> 23.783132 | CE1005: =AVERAGE(BW$6:BW1005) -> 0.90499281 | CF1005: =AVERAGE(BX$6:BX1005) -> 970.77486 | CG1005: =AVERAGE(BY$6:BY1005) -> 3658.9408 | CH1005: =AVERAGE(BZ$6:BZ1005) -> 2688.1659

Sheet SimulatedOutput-ConstantValue
B2: SIMULATION OF 1,000 TRIALS AT PRICE $180 AND LATE CANCELLATION FEE AT $50 | O2: TRACKING CONVERGENCE OF OUTPUT MEANS | X2: SIMULATION OF 1,000 TRIALS AT PRICE $180 AND LATE CANCELLATION FEE AT $70 | AK2: TRACKING CONVERGENCE OF OUTPUT MEANS | AT2: SIMULATION OF 1,000 TRIALS AT PRICE $150 AND LATE CANCELLATION FEE AT $50 | BG2: TRACKING CONVERGENCE OF OUTPUT MEANS | BP2: SIMULATION OF 1,000 TRIALS AT PRICE $150 AND LATE CANCELLATION FEE AT $70 | CC2: TRACKING CONVERGENCE OF OUTPUT MEANS
B4: Simulation trial | C4: Daily Online Bookings | D4: Daily Cancellations | E4: Daily Wak-ins | F4: Daily Miscellaneous Expenses | G4: Number of Occupied Rooms | H4: Showed Up Guests | I4: Overbooked Guests | J4: Daily Operation Cost | K4: Daily Total Revenue | L4: Total Daily Profit | M4: Sold Out | O4: Mean Number of Occupied Rooms | P4: Mean Showed Up Guests | Q4: Mean Overbooked Guests | R4: Mean Daily Operation Cost | S4: Mean Daily Total Revenue | T4: Mean Daily Profit | X4: Simulation trial | Y4: Daily Online Bookings | Z4: Daily Cancellations | AA4: Daily Wak-ins | AB4: Daily Miscellaneous Expenses | AC4: Number of Occupied Rooms | AD4: Showed Up Guests | AE4: Overbooked Guests | AF4: Daily Operation Cost | AG4: Daily Total Revenue | AH4: Total Daily Profit | AI4: Sold Out | AK4: Mean Number of Occupied Rooms | AL4: Mean Showed Up Guests | AM4: Mean Overbooked Guests | AN4: Mean Daily Operation Cost | AO4: Mean Daily Total Revenue | AP4: Mean Daily Profit | AT4: Simulation trial | AU4: Daily Online Bookings | AV4: Daily Cancellations | AW4: Daily Wak-ins | AX4: Daily Miscellaneous Expenses | AY4: Number of Occupied Rooms | AZ4: Showed Up Guests | BA4: Overbooked Guests | BB4: Daily Operation Cost | BC4: Daily Total Revenue | BD4: Total Daily Profit | BE4: Sold Out | BG4: Mean Number of Occupied Rooms | BH4: Mean Showed Up Guests | BI4: Mean Overbooked Guests | BJ4: Mean Daily Operation Cost | BK4: Mean Daily Total Revenue | BL4: Mean Daily Profit | BP4: Simulation trial | BQ4: Daily Online Bookings | BR4: Daily Cancellations | BS4: Daily Wak-ins | BT4: Daily Miscellaneous Expenses | BU4: Number of Occupied Rooms | BV4: Showed Up Guests | BW4: Overbooked Guests | BX4: Daily Operation Cost | BY4: Daily Total Revenue | BZ4: Total Daily Profit | CA4: Sold Out | CC4: Mean Number of Occupied Rooms | CD4: Mean Showed Up Guests | CE4: Mean Overbooked Guests | CF4: Mean Daily Operation Cost | CG4: Mean Daily Total Revenue | CH4: Mean Daily Profit
C5: 21.798163 | D5: 3 | E5: 4.4637704 | F5: 172.52438 | G5: 23.261934 | H5: 23.261934 | I5: 0 | J5: 870.38239 | K5: 4337.148 | L5: 3466.7656 | M5: No | Y5: 21.798163 | Z5: 3 | AA5: 4.4637704 | AB5: 172.52438 | AC5: 23.261934 | AD5: 23.261934 | AE5: 0 | AF5: 870.38239 | AG5: 4397.148 | AH5: 3526.7656 | AI5: No | AU5: 18.482157 | AV5: 4 | AW5: 5.7723953 | AX5: 172.52438 | AY5: 20.254552 | AZ5: 20.254552 | BA5: 0 | BB5: 780.16093 | BC5: 3238.1828 | BD5: 2458.0218 | BE5: No | BQ5: 18.482157 | BR5: 4 | BS5: 5.7723953 | BT5: 172.52438 | BU5: 20.254552 | BV5: 20.254552 | BW5: 0 | BX5: 780.16093 | BY5: 3318.1828 | BZ5: 2538.0218 | CA5: No
B6: 1 | C6: 14.719306 | D6: 3 | E6: 4.7363505 | F6: 138.10189 | G6: 16.455656 | H6: 16.455656 | I6: 0 | J6: 631.77158 | K6: 3112.0181 | L6: 2480.2466 | M6: No | O6: 16.455656 | P6: 16.455656 | Q6: 0 | R6: 631.77158 | S6: 3112.0181 | T6: 2480.2466 | X6: 1 | Y6: 14.40723 | Z6: 2 | AA6: 5.065749 | AB6: 148.323 | AC6: 17.472979 | AD6: 17.472979 | AE6: 0 | AF6: 672.51237 | AG6: 3285.1362 | AH6: 2612.6239 | AI6: No | AK6: 17.472979 | AL6: 17.472979 | AM6: 0 | AN6: 672.51237 | AO6: 3285.1362 | AP6: 2612.6239 | AT6: 1 | AU6: 25.501592 | AV6: 1 | AW6: 4.3516667 | AX6: 147.81181 | AY6: 25 | AZ6: 28.853259 | BA6: 3.8532587 | BB6: 1475.8006 | BC6: 3800 | BD6: 2324.1994 | BE6: Yes | BG6: 25 | BH6: 28.853259 | BI6: 3.8532587 | BJ6: 1475.8006 | BK6: 3800 | BL6: 2324.1994 | BP6: 1 | BQ6: 23.812715 | BR6: 3 | BS6: 3.0687738 | BT6: 152.83735 | BU6: 23.881489 | BV6: 23.881489 | BW6: 0 | BX6: 869.28202 | BY6: 3792.2234 | BZ6: 2922.9413 | CA6: No | CC6: 23.881489 | CD6: 23.881489 | CE6: 0 | CF6: 869.28202 | CG6: 3792.2234 | CH6: 2922.9413
B7: 2 | C7: 16.620744 | D7: 2 | E7: 2.16675 | F7: 135.52929 | G7: 16.787494 | H7: 16.787494 | I7: 0 | J7: 639.15412 | K7: 3121.749 | L7: 2482.5948 | M7: No | O7: 16.621575 | P7: 16.621575 | Q7: 0 | R7: 635.46285 | S7: 3116.8835 | T7: 2481.4207 | X7: 2 | Y7: 22.420042 | Z7: 3 | AA7: 5.1069444 | AB7: 162.8824 | AC7: 24.526986 | AD7: 24.526986 | AE7: 0 | AF7: 898.69199 | AG7: 4624.8575 | AH7: 3726.1656 | AI7: No | AK7: 20.999983 | AL7: 20.999983 | AM7: 0 | AN7: 785.60218 | AO7: 3954.9969 | AP7: 3169.3947 | AT7: 2 | AU7: 22.300092 | AV7: 3 | AW7: 5.8454143 | AX7: 145.95158 | AY7: 25 | AZ7: 25.145506 | BA7: 0.14550624 | BB7: 917.77751 | BC7: 3900 | BD7: 2982.2225 | BE7: Yes | BG7: 25 | BH7: 26.999382 | BI7: 1.9993825 | BJ7: 1196.7891 | BK7: 3850 | BL7: 2653.2109 | BP7: 2 | BQ7: 19.805232 | BR7: 3 | BS7: 6.5490619 | BT7: 155.38885 | BU7: 23.354294 | BV7: 23.354294 | BW7: 0 | BX7: 856.01766 | BY7: 3713.1441 | BZ7: 2857.1264 | CA7: No | CC7: 23.617891 | CD7: 23.617891 | CE7: 0 | CF7: 862.64984 | CG7: 3752.6837 | CH7: 2890.0339
B8: 3 | C8: 20.372887 | D8: 1 | E8: 5.8593617 | F8: 144.36615 | G8: 25 | H8: 25.232249 | I8: 0.23224878 | J8: 936.17093 | K8: 4550 | L8: 3613.8291 | M8: Yes | O8: 19.414383 | P8: 19.4918 | Q8: 0.077416261 | R8: 735.69888 | S8: 3594.589 | T8: 2858.8902 | X8: 3 | Y8: 17.96734 | Z8: 0 | AA8: 4.0370123 | AB8: 196.14337 | AC8: 22.004352 | AD8: 22.004352 | AE8: 0 | AF8: 856.27394 | AG8: 3960.7834 | AH8: 3104.5095 | AI8: No | AK8: 21.334773 | AL8: 21.334773 | AM8: 0 | AN8: 809.15943 | AO8: 3956.9257 | AP8: 3147.7663 | AT8: 3 | AU8: 28.517504 | AV8: 3 | AW8: 5.271076 | AX8: 139.21363 | AY8: 25 | AZ8: 30.78858 | BA8: 5.7885797 | BB8: 1757.5006 | BC8: 3900 | BD8: 2142.4994 | BE8: Yes | BG8: 25 | BH8: 28.262448 | BI8: 3.2624482 | BJ8: 1383.6929 | BK8: 3866.6667 | BL8: 2482.9738 | BP8: 3 | BQ8: 15.400527 | BR8: 3 | BS8: 3.3941752 | BT8: 157.10609 | BU8: 15.794702 | BV8: 15.794702 | BW8: 0 | BX8: 630.94715 | BY8: 2579.2053 | BZ8: 1948.2582 | CA8: No | CC8: 21.010162 | CD8: 21.010162 | CE8: 0 | CF8: 785.41561 | CG8: 3361.5242 | CH8: 2576.1086
B9: 4 | C9: 19.661217 | D9: 5 | E9: 4.0756897 | F9: 172.2097 | G9: 18.736907 | H9: 18.736907 | I9: 0 | J9: 734.31691 | K9: 3622.6433 | L9: 2888.3264 | M9: No | O9: 19.245014 | P9: 19.303077 | Q9: 0.058062196 | R9: 735.35339 | S9: 3601.6026 | T9: 2866.2492 | X9: 4 | Y9: 26.274062 | Z9: 3 | AA9: 2.2403709 | AB9: 182.40732 | AC9: 25 | AD9: 25.514433 | AE9: 0.51443264 | AF9: 1025.0052 | AG9: 4710 | AH9: 3684.9948 | AI9: Yes | AK9: 22.251079 | AL9: 22.379688 | AM9: 0.12860816 | AN9: 863.12087 | AO9: 4145.1943 | AP9: 3282.0734 | AT9: 4 | AU9: 19.943652 | AV9: 3 | AW9: 4.2229633 | AX9: 164.99824 | AY9: 21.166615 | AZ9: 21.166615 | BA9: 0 | BB9: 799.99669 | BC9: 3324.9923 | BD9: 2524.9956 | BE9: No | BG9: 24.041654 | BH9: 26.48849 | BI9: 2.4468362 | BJ9: 1237.7689 | BK9: 3731.2481 | BL9: 2493.4792 | BP9: 4 | BQ9: 22.68826 | BR9: 7 | BS9: 3.5818508 | BT9: 153.7758 | BU9: 19.270111 | BV9: 19.270111 | BW9: 0 | BX9: 731.87912 | BY9: 3380.5166 | BZ9: 2648.6375 | CA9: No | CC9: 20.575149 | CD9: 20.575149 | CE9: 0 | CF9: 772.03149 | CG9: 3366.2723 | CH9: 2594.2408
B10: 5 | C10: 27.930813 | D10: 2 | E10: 2.8689553 | F10: 151.75578 | G10: 25 | H10: 28.799768 | I10: 3.7997681 | J10: 1585.714 | K10: 4600 | L10: 3014.286 | M10: Yes | O10: 20.396012 | P10: 21.202415 | Q10: 0.80640338 | R10: 905.42552 | S10: 3801.2821 | T10: 2895.8566 | X10: 5 | Y10: 16.223849 | Z10: 2 | AA10: 2.1953134 | AB10: 155.06568 | AC10: 16.419162 | AD10: 16.419162 | AE10: 0 | AF10: 647.64054 | AG10: 3095.4492 | AH10: 2447.8086 | AI10: No | AK10: 21.084696 | AL10: 21.187583 | AM10: 0.10288653 | AN10: 820.02481 | AO10: 3935.2453 | AP10: 3115.2205 | AT10: 5 | AU10: 21.866361 | AV10: 3 | AW10: 6.8166311 | AX10: 123.3384 | AY10: 25 | AZ10: 25.682992 | BA10: 0.68299193 | BB10: 975.78719 | BC10: 3900 | BD10: 2924.2128 | BE10: Yes | BG10: 24.233323 | BH10: 26.32739 | BI10: 2.0940673 | BJ10: 1185.3725 | BK10: 3764.9985 | BL10: 2579.6259 | BP10: 5 | BQ10: 21.561186 | BR10: 2 | BS10: 6.12398 | BT10: 138.94504 | BU10: 25 | BV10: 25.685166 | BW10: 0.68516601 | BX10: 991.71994 | BY10: 3890 | BZ10: 2898.2801 | CA10: Yes | CC10: 21.460119 | CD10: 21.597152 | CE10: 0.1370332 | CF10: 815.96918 | CG10: 3471.0179 | CH10: 2655.0487
B11: 6 | C11: 17.886634 | D11: 2 | E11: 5.6731206 | F11: 119.11992 | G11: 21.559754 | H11: 21.559754 | I11: 0 | J11: 765.91255 | K11: 3980.7558 | L11: 3214.8432 | M11: No | O11: 20.589969 | P11: 21.261971 | Q11: 0.67200282 | R11: 882.17336 | S11: 3831.1944 | T11: 2949.021 | X11: 6 | Y11: 26.513457 | Z11: 1 | AA11: 5.2303486 | AB11: 179.13944 | AC11: 25 | AD11: 30.743805 | AE11: 5.7438054 | AF11: 1963.0244 | AG11: 4570 | AH11: 2606.9756 | AI11: Yes | AK11: 21.737247 | AL11: 22.780286 | AM11: 1.0430397 | AN11: 1010.5247 | AO11: 4041.0377 | AP11: 3030.513 | AT11: 6 | AU11: 24.299003 | AV11: 3 | AW11: 3.2152543 | AX11: 173.87064 | AY11: 24.514258 | AZ11: 24.514258 | BA11: 0 | BB11: 909.29837 | BC11: 3827.1387 | BD11: 2917.8403 | BE11: No | BG11: 24.280145 | BH11: 26.025202 | BI11: 1.7450561 | BJ11: 1139.3602 | BK11: 3775.3552 | BL11: 2635.995 | BP11: 6 | BQ11: 22.092164 | BR11: 1 | BS11: 6.4192583 | BT11: 183.66273 | BU11: 25 | BV11: 27.511422 | BW11: 2.5114219 | BX11: 1310.376 | BY11: 3820 | BZ11: 2509.624 | CA11: Yes | CC11: 22.050099 | CD11: 22.582864 | CE11: 0.53276466 | CF11: 898.37032 | CG11: 3529.1816 | CH11: 2630.8112
B12: 7 | C12: 17.220439 | D12: 1 | E12: 5.2474144 | F12: 124.91459 | G12: 21.467854 | H12: 21.467854 | I12: 0 | J12: 768.9502 | K12: 3914.2136 | L12: 3145.2634 | M12: No | O12: 20.715381 | P12: 21.291383 | Q12: 0.57600242 | R12: 865.99862 | S12: 3843.0543 | T12: 2977.0556 | X12: 7 | Y12: 20.36569 | Z12: 2 | AA12: 5.1092415 | AB12: 145.59094 | AC12: 23.474931 | AD12: 23.474931 | AE12: 0 | AF12: 849.83888 | AG12: 4365.4876 | AH12: 3515.6487 | AI12: No | AK12: 21.985487 | AL12: 22.879521 | AM12: 0.894034 | AN12: 987.56962 | AO12: 4087.3877 | AP12: 3099.8181 | AT12: 7 | AU12: 24.469041 | AV12: 2 | AW12: 4.17566 | AX12: 137.95221 | AY12: 25 | AZ12: 26.644701 | BA12: 1.6447014 | BB12: 1134.6574 | BC12: 3850 | BD12: 2715.3426 | BE12: Yes | BG12: 24.382982 | BH12: 26.113702 | BI12: 1.7307197 | BJ12: 1138.6883 | BK12: 3786.0187 | BL12: 2647.3304 | BP12: 7 | BQ12: 21.362302 | BR12: 3 | BS12: 3.0358347 | BT12: 148.61179 | BU12: 21.398137 | BV12: 21.398137 | BW12: 0 | BX12: 790.5559 | BY12: 3419.7206 | BZ12: 2629.1647 | CA12: No | CC12: 21.956962 | CD12: 22.413617 | CE12: 0.45665542 | CF12: 882.96826 | CG12: 3513.5443 | CH12: 2630.576
B13: 8 | C13: 19.452401 | D13: 1 | E13: 2.1938767 | F13: 170.30624 | G13: 20.646278 | H13: 20.646278 | I13: 0 | J13: 789.69457 | K13: 3766.33 | L13: 2976.6354 | M13: No | O13: 20.706743 | P13: 21.210745 | Q13: 0.50400211 | R13: 856.46061 | S13: 3833.4637 | T13: 2977.0031 | X13: 8 | Y13: 15.038664 | Z13: 2 | AA13: 4.7612312 | AB13: 120.39955 | AC13: 17.799895 | AD13: 17.799895 | AE13: 0 | AF13: 654.39641 | AG13: 3343.9811 | AH13: 2689.5847 | AI13: No | AK13: 21.462288 | AL13: 22.244568 | AM13: 0.78227975 | AN13: 945.92297 | AO13: 3994.4619 | AP13: 3048.5389 | AT13: 8 | AU13: 22.51636 | AV13: 4 | AW13: 3.4046078 | AX13: 137.59421 | AY13: 21.920968 | AZ13: 21.920968 | BA13: 0 | BB13: 795.22325 | BC13: 3488.1452 | BD13: 2692.922 | BE13: No | BG13: 24.07523 | BH13: 25.58961 | BI13: 1.5143797 | BJ13: 1095.7552 | BK13: 3748.7845 | BL13: 2653.0293 | BP13: 8 | BQ13: 20.036796 | BR13: 2 | BS13: 5.1373291 | BT13: 135.25363 | BU13: 23.174125 | BV13: 23.174125 | BW13: 0 | BX13: 830.4774 | BY13: 3616.1188 | BZ13: 2785.6414 | CA13: No | CC13: 22.109107 | CD13: 22.508681 | CE13: 0.39957349 | CF13: 876.4069 | CG13: 3526.3661 | CH13: 2649.9592
